<?xml version="1.0" ?>
<robot name="Puguette">

<material name="silver">
  <color rgba="0.700 0.700 0.700 1.000"/>
</material>

<link name="base_link">
  <inertial>
    <origin xyz="-0.03180841476638693 0.07427733536146494 -0.001579457934195628" rpy="0 0 0"/>
    <mass value="12"/>
    <inertia ixx="0.327491657031869" iyy="1.2968956364918554" izz="1.4405923953428628" ixy="-2.1389042884067955e-08" iyz="-1.2380721448046472e-14" ixz="4.139754511411908e-12"/>
  </inertial>
  <visual>
    <origin xyz="0 0 0" rpy="0 0 0"/>
    <geometry>
      <mesh filename="meshes/base_link.stl" scale="0.001 0.001 0.001"/>
    </geometry>
    <material name="silver"/>
    <material/>
  </visual>
  <collision>
    <origin xyz="0 0 0" rpy="0 0 0"/>
    <geometry>
      <mesh filename="meshes/base_link.stl" scale="0.001 0.001 0.001"/>
    </geometry>
  </collision>
</link>

<link name="FR_Joint1">
  <inertial>
    <origin xyz="-0.07386142547452285 0.0065706579307107105 0.0004947012899105428" rpy="0 0 0"/>
    <mass value="1.2"/>
    <inertia ixx="0.02073467165454268" iyy="0.029302842731540935" izz="0.022688124373751117" ixy="2.8210234283010394e-06" iyz="-0.00011229052125653872" ixz="9.865032907056814e-08"/>
  </inertial>
  <visual>
    <origin xyz="0.254809 -0.149277 0.001579" rpy="0 0 0"/>
    <geometry>
      <mesh filename="meshes/FR_Joint1.stl" scale="0.001 0.001 0.001"/>
    </geometry>
    <material name="silver"/>
    <material/>
  </visual>
  <collision>
    <origin xyz="0.254809 -0.149277 0.001579" rpy="0 0 0"/>
    <geometry>
      <mesh filename="meshes/FR_Joint1.stl" scale="0.001 0.001 0.001"/>
    </geometry>
  </collision>
</link>

<link name="FR_Upper_Leg1">
  <inertial>
    <origin xyz="0.00020261207237287637 0.07283703782473894 -0.06601468887803173" rpy="0 0 0"/>
    <mass value="1.2"/>
    <inertia ixx="0.12811236977021634" iyy="0.13454231816145867" izz="0.02205492463934111" ixy="9.342399132394874e-05" iyz="0.019800810852604073" ixz="-0.00012115075615776183"/>
  </inertial>
  <visual>
    <origin xyz="0.328688 -0.198307 0.000613" rpy="0 0 0"/>
    <geometry>
      <mesh filename="meshes/FR_Upper_Leg1.stl" scale="0.001 0.001 0.001"/>
    </geometry>
    <material name="silver"/>
    <material/>
  </visual>
  <collision>
    <origin xyz="0.328688 -0.198307 0.000613" rpy="0 0 0"/>
    <geometry>
      <mesh filename="meshes/FR_Upper_Leg1.stl" scale="0.001 0.001 0.001"/>
    </geometry>
  </collision>
</link>

<link name="FR_Lower_Leg1">
  <inertial>
    <origin xyz="-1.1094217650109428e-07 0.010539661618046203 -0.06653363488178754" rpy="0 0 0"/>
    <mass value="1.2"/>
    <inertia ixx="0.013026958191979854" iyy="0.013195241180532613" izz="0.0005121782460532076" ixy="9.54236689665322e-14" iyz="0.00025033984765562844" ixz="1.7631729409828267e-12"/>
  </inertial>
  <visual>
    <origin xyz="0.328688 -0.326343 0.280626" rpy="0 0 0"/>
    <geometry>
      <mesh filename="meshes/FR_Lower_Leg1.stl" scale="0.001 0.001 0.001"/>
    </geometry>
    <material name="silver"/>
    <material/>
  </visual>
  <collision>
    <origin xyz="0.328688 -0.326343 0.280626" rpy="0 0 0"/>
    <geometry>
      <mesh filename="meshes/FR_Lower_Leg1.stl" scale="0.001 0.001 0.001"/>
    </geometry>
  </collision>
</link>

<link name="FL_Joint1">
  <inertial>
    <origin xyz="-0.07386142620000508 -0.006569979700954141 -0.0004952540320456731" rpy="0 0 0"/>
    <mass value="1.2"/>
    <inertia ixx="0.02073467165454188" iyy="0.02930284273154049" izz="0.022688124373751117" ixy="-2.8210234282177726e-06" iyz="-0.00011229052125655316" ixz="-9.865032879648183e-08"/>
  </inertial>
  <visual>
    <origin xyz="0.254809 0.000723 0.001579" rpy="0 0 0"/>
    <geometry>
      <mesh filename="meshes/FL_Joint1.stl" scale="0.001 0.001 0.001"/>
    </geometry>
    <material name="silver"/>
    <material/>
  </visual>
  <collision>
    <origin xyz="0.254809 0.000723 0.001579" rpy="0 0 0"/>
    <geometry>
      <mesh filename="meshes/FL_Joint1.stl" scale="0.001 0.001 0.001"/>
    </geometry>
  </collision>
</link>

<link name="FL_Upper_Leg1">
  <inertial>
    <origin xyz="-0.000203213226204646 -0.07283635959498225 -0.06601498909918865" rpy="0 0 0"/>
    <mass value="1.2"/>
    <inertia ixx="0.12811236944403465" iyy="0.13454231745330403" izz="0.022054924257367547" ixy="9.342398974415689e-05" iyz="-0.019800810853072476" ixz="0.0001211514656932755"/>
  </inertial>
  <visual>
    <origin xyz="0.328688 0.049753 0.002546" rpy="0 0 0"/>
    <geometry>
      <mesh filename="meshes/FL_Upper_Leg1.stl" scale="0.001 0.001 0.001"/>
    </geometry>
    <material name="silver"/>
    <material/>
  </visual>
  <collision>
    <origin xyz="0.328688 0.049753 0.002546" rpy="0 0 0"/>
    <geometry>
      <mesh filename="meshes/FL_Upper_Leg1.stl" scale="0.001 0.001 0.001"/>
    </geometry>
  </collision>
</link>

<link name="FL_Lower_Leg1">
  <inertial>
    <origin xyz="-4.902062988865197e-07 -0.01053998338829007 -0.06653293510135605" rpy="0 0 0"/>
    <mass value="1.2"/>
    <inertia ixx="0.013026958191979465" iyy="0.013195241180532669" izz="0.0005121782460534297" ixy="9.600653605446041e-14" iyz="-0.00025033984765573947" ixz="-1.7638390747976018e-12"/>
  </inertial>
  <visual>
    <origin xyz="0.328688 0.177788 0.28256" rpy="0 0 0"/>
    <geometry>
      <mesh filename="meshes/FL_Lower_Leg1.stl" scale="0.001 0.001 0.001"/>
    </geometry>
    <material name="silver"/>
    <material/>
  </visual>
  <collision>
    <origin xyz="0.328688 0.177788 0.28256" rpy="0 0 0"/>
    <geometry>
      <mesh filename="meshes/FL_Lower_Leg1.stl" scale="0.001 0.001 0.001"/>
    </geometry>
  </collision>
</link>

<link name="BL_Joint1">
  <inertial>
    <origin xyz="0.07386125382469919 -0.00656997970095369 0.0004947012899100759" rpy="0 0 0"/>
    <mass value="1.2"/>
    <inertia ixx="0.020734671654541965" iyy="0.02930284273154049" izz="0.022688124373750784" ixy="2.8210234282385893e-06" iyz="0.00011229052125656136" ixz="-9.865032871408247e-08"/>
  </inertial>
  <visual>
    <origin xyz="-0.191192 0.000723 0.001579" rpy="0 0 0"/>
    <geometry>
      <mesh filename="meshes/BL_Joint1.stl" scale="0.001 0.001 0.001"/>
    </geometry>
    <material name="silver"/>
    <material/>
  </visual>
  <collision>
    <origin xyz="-0.191192 0.000723 0.001579" rpy="0 0 0"/>
    <geometry>
      <mesh filename="meshes/BL_Joint1.stl" scale="0.001 0.001 0.001"/>
    </geometry>
  </collision>
</link>

<link name="BL_Upper_Leg1">
  <inertial>
    <origin xyz="-0.0002027837275550004 -0.07283635959498128 -0.06601468887962054" rpy="0 0 0"/>
    <mass value="1.2"/>
    <inertia ixx="0.12811236944403484" iyy="0.13454231745330314" izz="0.022054924257367214" ixy="9.342398974443444e-05" iyz="-0.019800810853072087" ixz="0.00012115146569399715"/>
  </inertial>
  <visual>
    <origin xyz="-0.265071 0.049753 0.000613" rpy="0 0 0"/>
    <geometry>
      <mesh filename="meshes/BL_Upper_Leg1.stl" scale="0.001 0.001 0.001"/>
    </geometry>
    <material name="silver"/>
    <material/>
  </visual>
  <collision>
    <origin xyz="-0.265071 0.049753 0.000613" rpy="0 0 0"/>
    <geometry>
      <mesh filename="meshes/BL_Upper_Leg1.stl" scale="0.001 0.001 0.001"/>
    </geometry>
  </collision>
</link>

<link name="BL_Lower_Leg1">
  <inertial>
    <origin xyz="-6.069636965255754e-08 -0.010539983396232466 -0.06653363490149644" rpy="0 0 0"/>
    <mass value="1.2"/>
    <inertia ixx="0.013026958190714921" iyy="0.013195241178591055" izz="0.0005121782446798617" ixy="-3.5889347049788967e-13" iyz="-0.00025033984685920996" ixz="-2.6839086508800847e-12"/>
  </inertial>
  <visual>
    <origin xyz="-0.265071 0.177788 0.280626" rpy="0 0 0"/>
    <geometry>
      <mesh filename="meshes/BL_Lower_Leg1.stl" scale="0.001 0.001 0.001"/>
    </geometry>
    <material name="silver"/>
    <material/>
  </visual>
  <collision>
    <origin xyz="-0.265071 0.177788 0.280626" rpy="0 0 0"/>
    <geometry>
      <mesh filename="meshes/BL_Lower_Leg1.stl" scale="0.001 0.001 0.001"/>
    </geometry>
  </collision>
</link>

<link name="BR_Joint1">
  <inertial>
    <origin xyz="0.07386125309921679 0.006570657930710683 -0.0004952540320459554" rpy="0 0 0"/>
    <mass value="1.2"/>
    <inertia ixx="0.02073467165454207" iyy="0.029302842731539935" izz="0.02268812437375045" ixy="-2.821023428134506e-06" iyz="0.00011229052125656929" ixz="9.865032874183804e-08"/>
  </inertial>
  <visual>
    <origin xyz="-0.191192 -0.149277 0.001579" rpy="0 0 0"/>
    <geometry>
      <mesh filename="meshes/BR_Joint1.stl" scale="0.001 0.001 0.001"/>
    </geometry>
    <material name="silver"/>
    <material/>
  </visual>
  <collision>
    <origin xyz="-0.191192 -0.149277 0.001579" rpy="0 0 0"/>
    <geometry>
      <mesh filename="meshes/BR_Joint1.stl" scale="0.001 0.001 0.001"/>
    </geometry>
  </collision>
</link>

<link name="BR_Upper_Leg1">
  <inertial>
    <origin xyz="0.00020304012542721184 0.07283703782473855 -0.06601498909918857" rpy="0 0 0"/>
    <mass value="1.2"/>
    <inertia ixx="0.12811236944403492" iyy="0.13454231745330403" izz="0.022054924257367325" ixy="9.34239897452116e-05" iyz="0.019800810853072448" ixz="-0.00012115146569055546"/>
  </inertial>
  <visual>
    <origin xyz="-0.265071 -0.198307 0.002546" rpy="0 0 0"/>
    <geometry>
      <mesh filename="meshes/BR_Upper_Leg1.stl" scale="0.001 0.001 0.001"/>
    </geometry>
    <material name="silver"/>
    <material/>
  </visual>
  <collision>
    <origin xyz="-0.265071 -0.198307 0.002546" rpy="0 0 0"/>
    <geometry>
      <mesh filename="meshes/BR_Upper_Leg1.stl" scale="0.001 0.001 0.001"/>
    </geometry>
  </collision>
</link>

<link name="BR_Lower_Leg1">
  <inertial>
    <origin xyz="3.132389264082214e-07 0.010539661365388864 -0.06653294310138463" rpy="0 0 0"/>
    <mass value="1.2"/>
    <inertia ixx="0.013026957174682718" iyy="0.013195239953289528" izz="0.0005121780084318961" ixy="1.4651890811734347e-11" iyz="0.00025033987776187927" ixz="4.6293774369488006e-10"/>
  </inertial>
  <visual>
    <origin xyz="-0.265071 -0.326343 0.28256" rpy="0 0 0"/>
    <geometry>
      <mesh filename="meshes/BR_Lower_Leg1.stl" scale="0.001 0.001 0.001"/>
    </geometry>
    <material name="silver"/>
    <material/>
  </visual>
  <collision>
    <origin xyz="-0.265071 -0.326343 0.28256" rpy="0 0 0"/>
    <geometry>
      <mesh filename="meshes/BR_Lower_Leg1.stl" scale="0.001 0.001 0.001"/>
    </geometry>
  </collision>
</link>

<joint name="Rev53" type="revolute">
  <origin xyz="-0.254809 0.149277 -0.001579" rpy="0 0 0"/>
  <parent link="base_link"/>
  <child link="FR_Joint1"/>
  <axis xyz="-1.0 -0.0 0.0"/>
  <limit upper="1.570796" lower="-1.570796" effort="100" velocity="100"/>
</joint>
<transmission name="Rev53_tran">
  <type>transmission_interface/SimpleTransmission</type>
  <joint name="Rev53">
    <hardwareInterface>PositionJointInterface</hardwareInterface>
  </joint>
  <actuator name="Rev53_actr">
    <hardwareInterface>PositionJointInterface</hardwareInterface>
    <mechanicalReduction>1</mechanicalReduction>
  </actuator>
</transmission>

<joint name="Rev57" type="continuous">
  <origin xyz="-0.073879 0.04903 0.000966" rpy="0 0 0"/>
  <parent link="FR_Joint1"/>
  <child link="FR_Upper_Leg1"/>
  <axis xyz="-0.0 -1.0 0.0"/>
</joint>
<transmission name="Rev57_tran">
  <type>transmission_interface/SimpleTransmission</type>
  <joint name="Rev57">
    <hardwareInterface>PositionJointInterface</hardwareInterface>
  </joint>
  <actuator name="Rev57_actr">
    <hardwareInterface>PositionJointInterface</hardwareInterface>
    <mechanicalReduction>1</mechanicalReduction>
  </actuator>
</transmission>

<joint name="Rev65" type="continuous">
  <origin xyz="0.0 0.128036 -0.280013" rpy="0 0 0"/>
  <parent link="FR_Upper_Leg1"/>
  <child link="FR_Lower_Leg1"/>
  <axis xyz="-0.0 -1.0 0.0"/>
</joint>
<transmission name="Rev65_tran">
  <type>transmission_interface/SimpleTransmission</type>
  <joint name="Rev65">
    <hardwareInterface>PositionJointInterface</hardwareInterface>
  </joint>
  <actuator name="Rev65_actr">
    <hardwareInterface>PositionJointInterface</hardwareInterface>
    <mechanicalReduction>1</mechanicalReduction>
  </actuator>
</transmission>

<joint name="Rev69" type="revolute">
  <origin xyz="-0.254809 -0.000723 -0.001579" rpy="0 0 0"/>
  <parent link="base_link"/>
  <child link="FL_Joint1"/>
  <axis xyz="-1.0 -0.0 0.0"/>
  <limit upper="1.570796" lower="-1.570796" effort="100" velocity="100"/>
</joint>
<transmission name="Rev69_tran">
  <type>transmission_interface/SimpleTransmission</type>
  <joint name="Rev69">
    <hardwareInterface>PositionJointInterface</hardwareInterface>
  </joint>
  <actuator name="Rev69_actr">
    <hardwareInterface>PositionJointInterface</hardwareInterface>
    <mechanicalReduction>1</mechanicalReduction>
  </actuator>
</transmission>

<joint name="Rev70" type="continuous">
  <origin xyz="-0.073879 -0.04903 -0.000967" rpy="0 0 0"/>
  <parent link="FL_Joint1"/>
  <child link="FL_Upper_Leg1"/>
  <axis xyz="0.0 1.0 -0.0"/>
</joint>
<transmission name="Rev70_tran">
  <type>transmission_interface/SimpleTransmission</type>
  <joint name="Rev70">
    <hardwareInterface>PositionJointInterface</hardwareInterface>
  </joint>
  <actuator name="Rev70_actr">
    <hardwareInterface>PositionJointInterface</hardwareInterface>
    <mechanicalReduction>1</mechanicalReduction>
  </actuator>
</transmission>

<joint name="Rev71" type="continuous">
  <origin xyz="0.0 -0.128035 -0.280014" rpy="0 0 0"/>
  <parent link="FL_Upper_Leg1"/>
  <child link="FL_Lower_Leg1"/>
  <axis xyz="0.0 1.0 -0.0"/>
</joint>
<transmission name="Rev71_tran">
  <type>transmission_interface/SimpleTransmission</type>
  <joint name="Rev71">
    <hardwareInterface>PositionJointInterface</hardwareInterface>
  </joint>
  <actuator name="Rev71_actr">
    <hardwareInterface>PositionJointInterface</hardwareInterface>
    <mechanicalReduction>1</mechanicalReduction>
  </actuator>
</transmission>

<joint name="Rev72" type="revolute">
  <origin xyz="0.191192 -0.000723 -0.001579" rpy="0 0 0"/>
  <parent link="base_link"/>
  <child link="BL_Joint1"/>
  <axis xyz="1.0 0.0 0.0"/>
  <limit upper="1.570796" lower="-1.570796" effort="100" velocity="100"/>
</joint>
<transmission name="Rev72_tran">
  <type>transmission_interface/SimpleTransmission</type>
  <joint name="Rev72">
    <hardwareInterface>PositionJointInterface</hardwareInterface>
  </joint>
  <actuator name="Rev72_actr">
    <hardwareInterface>PositionJointInterface</hardwareInterface>
    <mechanicalReduction>1</mechanicalReduction>
  </actuator>
</transmission>

<joint name="Rev73" type="continuous">
  <origin xyz="0.073879 -0.04903 0.000966" rpy="0 0 0"/>
  <parent link="BL_Joint1"/>
  <child link="BL_Upper_Leg1"/>
  <axis xyz="0.0 1.0 0.0"/>
</joint>
<transmission name="Rev73_tran">
  <type>transmission_interface/SimpleTransmission</type>
  <joint name="Rev73">
    <hardwareInterface>PositionJointInterface</hardwareInterface>
  </joint>
  <actuator name="Rev73_actr">
    <hardwareInterface>PositionJointInterface</hardwareInterface>
    <mechanicalReduction>1</mechanicalReduction>
  </actuator>
</transmission>

<joint name="Rev74" type="continuous">
  <origin xyz="0.0 -0.128035 -0.280013" rpy="0 0 0"/>
  <parent link="BL_Upper_Leg1"/>
  <child link="BL_Lower_Leg1"/>
  <axis xyz="0.0 1.0 0.0"/>
</joint>
<transmission name="Rev74_tran">
  <type>transmission_interface/SimpleTransmission</type>
  <joint name="Rev74">
    <hardwareInterface>PositionJointInterface</hardwareInterface>
  </joint>
  <actuator name="Rev74_actr">
    <hardwareInterface>PositionJointInterface</hardwareInterface>
    <mechanicalReduction>1</mechanicalReduction>
  </actuator>
</transmission>

<joint name="Rev75" type="revolute">
  <origin xyz="0.191192 0.149277 -0.001579" rpy="0 0 0"/>
  <parent link="base_link"/>
  <child link="BR_Joint1"/>
  <axis xyz="1.0 0.0 0.0"/>
  <limit upper="1.570796" lower="-1.570796" effort="100" velocity="100"/>
</joint>
<transmission name="Rev75_tran">
  <type>transmission_interface/SimpleTransmission</type>
  <joint name="Rev75">
    <hardwareInterface>PositionJointInterface</hardwareInterface>
  </joint>
  <actuator name="Rev75_actr">
    <hardwareInterface>PositionJointInterface</hardwareInterface>
    <mechanicalReduction>1</mechanicalReduction>
  </actuator>
</transmission>

<joint name="Rev76" type="continuous">
  <origin xyz="0.073879 0.04903 -0.000967" rpy="0 0 0"/>
  <parent link="BR_Joint1"/>
  <child link="BR_Upper_Leg1"/>
  <axis xyz="-0.0 -1.0 -0.0"/>
</joint>
<transmission name="Rev76_tran">
  <type>transmission_interface/SimpleTransmission</type>
  <joint name="Rev76">
    <hardwareInterface>PositionJointInterface</hardwareInterface>
  </joint>
  <actuator name="Rev76_actr">
    <hardwareInterface>PositionJointInterface</hardwareInterface>
    <mechanicalReduction>1</mechanicalReduction>
  </actuator>
</transmission>

<joint name="Rev77" type="continuous">
  <origin xyz="0.0 0.128036 -0.280014" rpy="0 0 0"/>
  <parent link="BR_Upper_Leg1"/>
  <child link="BR_Lower_Leg1"/>
  <axis xyz="-0.0 -1.0 -0.0"/>
</joint>
<transmission name="Rev77_tran">
  <type>transmission_interface/SimpleTransmission</type>
  <joint name="Rev77">
    <hardwareInterface>PositionJointInterface</hardwareInterface>
  </joint>
  <actuator name="Rev77_actr">
    <hardwareInterface>PositionJointInterface</hardwareInterface>
    <mechanicalReduction>1</mechanicalReduction>
  </actuator>
</transmission>

</robot>
